Workbook

Sheet Assumptions
A1: CapexIQ — Assumptions
A2: Purchase cost | B2: 65000000
A3: Installation cost | B3: 7500000
A4: Initial investment | B4: =$B$2+$B$3
A5: Usage per day | B5: 25
A6: Working days per month | B6: 25
A7: Variable cost per use | B7: 3350
A8: Fixed cost per month | B8: 675000
A9: Useful life (years) | B9: 13
A10: Discount rate (%) | B10: 12.5
A11: Salvage value (%) | B11: 5
A12: Financing type | B12: Loan
A13: Loan down payment | B13: 12500000
A14: Loan interest rate (%) | B14: 11.5
A15: Loan/lease tenure (months) | B15: 60
A16: Lease rental per month | B16: 0
A17: Warranty years | B17: 5
A18: CMC years | B18: 3
A19: CMC annual cost | B19: 4225000
A20: AMC annual cost | B20: 1462500
A21: Ramp: months 1-3 (%) | B21: 50
A22: Ramp: months 4-6 (%) | B22: 70
A23: Ramp: months 7-12 (%) | B23: 85
A24: Ramp: year 2+ (%) | B24: 100
A25: Payer mix
A26: Payer | B26: Share of volume % | C26: Billed tariff (₹) | D26: Realization % (post-deduction) | E26: Collection delay (days)
A27: Private cash | B27: 55 | C27: 8500 | D27: 96.04 | E27: 7
A28: Insurance / TPA | B28: 25 | C28: 7800 | D28: 77.44 | E28: 45
A29: Corporate credit | B29: 10 | C29: 8200 | D29: 84.64 | E29: 30
A30: PM-JAY / government | B30: 10 | C30: 6500 | D30: 72.25 | E30: 60
A31: Other | B31: 0 | C31: 8500 | D31: 100 | E31: 0
A32: Billed per use (weighted) | B32: =SUMPRODUCT($B$27:$B$31,$C$27:$C$31)/100
A33: Realized revenue per use | B33: =SUMPRODUCT($B$27:$B$31,$C$27:$C$31,$D$27:$D$31)/10000
A34: Maintenance overrides (%, blank = use standard schedule)
A35: Year 1 override | B35: 0
A36: Year 2 override | B36: 0
A37: Year 3 override | B37: 0
A38: Year 4 override | B38: 0
A39: Year 5 override | B39: 0
A40: Year 6 override | B40: 6.5
...

Sheet Monthly
A1: Month # | B1: Year # | C1: Billed revenue | D1: Ramp % | E1: Realized revenue | F1: Variable cost | G1: Fixed cost | H1: Maintenance cost | I1: EMI / lease | J1: Net cash flow after financing | K1: Cash received — Private cash | L1: Cash received — Insurance / TPA | M1: Cash received — Corporate credit | N1: Cash received — PM-JAY / government | O1: Cash received — Other | P1: Cash received — Total | R1: Monthly payment (EMI/lease) | S1: =IF(Assumptions!$B$12="Loan",-PMT(Assumptions!$B$14/12/100,Assumptions!$B$15,Assumptions!$B$4-Assumptions!$B$13),IF(Assumptions!$B$12="Lease",Assumptions!$B$16,0))
A2: 1 | B2: 1 | C2: =Assumptions!$B$5*Assumptions!$B$32*Assumptions!$B$6*D2 | D2: =IF(A2<=3,Assumptions!$B$21,IF(A2<=6,Assumptions!$B$22,IF(A2<=12,Assumptions!$B$23,Assumptions!$B$24)))/100 | E2: =Assumptions!$B$5*Assumptions!$B$33*Assumptions!$B$6*D2 | F2: =Assumptions!$B$5*Assumptions!$B$7*Assumptions!$B$6*D2 | G2: =Assumptions!$B$8 | H2: =IF(INDEX(Assumptions!$B$35:$B$47,B2)<>"",INDEX(Assumptions!$B$35:$B$47,B2)/100*Assumptions!$B$2,IF(B2<=Assumptions!$B$17,0,IF(B2<=Assumptions!$B$17+Assumptions!$B$18,Assumptions!$B$19,Assumptions!$B$20)))/12 | I2: =IF(Assumptions!$B$12="Cash",0,IF(A2<=Assumptions!$B$15,Monthly!$S$1,0)) | J2: =E2-F2-G2-H2-I2 | K2: =IF(AND(A2-CEILING(Assumptions!$E$27/30,1)>=1,A2-CEILING(Assumptions!$E$27/30,1)<=156),INDEX($E$2:$E$157,A2-CEILING(Assumptions!$E$27/30,1))*Assumptions!$B$27/100,0) | L2: =IF(AND(A2-CEILING(Assumptions!$E$28/30,1)>=1,A2-CEILING(Assumptions!$E$28/30,1)<=156),INDEX($E$2:$E$157,A2-CEILING(Assumptions!$E$28/30,1))*Assumptions!$B$28/100,0) | M2: =IF(AND(A2-CEILING(Assumptions!$E$29/30,1)>=1,A2-CEILING(Assumptions!$E$29/30,1)<=156),INDEX($E$2:$E$157,A2-CEILING(Assumptions!$E$29/30,1))*Assumptions!$B$29/100,0) | N2: =IF(AND(A2-CEILING(Assumptions!$E$30/30,1)>=1,A2-CEILING(Assumptions!$E$30/30,1)<=156),INDEX($E$2:$E$157,A2-CEILING(Assumptions!$E$30/30,1))*Assumptions!$B$30/100,0) | O2: =IF(AND(A2-CEILING(Assumptions!$E$31/30,1)>=1,A2-CEILING(Assumptions!$E$31/30,1)<=156),INDEX($E$2:$E$157,A2-CEILING(Assumptions!$E$31/30,1))*Assumptions!$B$31/100,0) | P2: =K2+L2+M2+N2+O2
A3: 2 | B3: 1 | C3: =Assumptions!$B$5*Assumptions!$B$32*Assumptions!$B$6*D3 | D3: =IF(A3<=3,Assumptions!$B$21,IF(A3<=6,Assumptions!$B$22,IF(A3<=12,Assumptions!$B$23,Assumptions!$B$24)))/100 | E3: =Assumptions!$B$5*Assumptions!$B$33*Assumptions!$B$6*D3 | F3: =Assumptions!$B$5*Assumptions!$B$7*Assumptions!$B$6*D3 | G3: =Assumptions!$B$8 | H3: =IF(INDEX(Assumptions!$B$35:$B$47,B3)<>"",INDEX(Assumptions!$B$35:$B$47,B3)/100*Assumptions!$B$2,IF(B3<=Assumptions!$B$17,0,IF(B3<=Assumptions!$B$17+Assumptions!$B$18,Assumptions!$B$19,Assumptions!$B$20)))/12 | I3: =IF(Assumptions!$B$12="Cash",0,IF(A3<=Assumptions!$B$15,Monthly!$S$1,0)) | J3: =E3-F3-G3-H3-I3 | K3: =IF(AND(A3-CEILING(Assumptions!$E$27/30,1)>=1,A3-CEILING(Assumptions!$E$27/30,1)<=156),INDEX($E$2:$E$157,A3-CEILING(Assumptions!$E$27/30,1))*Assumptions!$B$27/100,0) | L3: =IF(AND(A3-CEILING(Assumptions!$E$28/30,1)>=1,A3-CEILING(Assumptions!$E$28/30,1)<=156),INDEX($E$2:$E$157,A3-CEILING(Assumptions!$E$28/30,1))*Assumptions!$B$28/100,0) | M3: =IF(AND(A3-CEILING(Assumptions!$E$29/30,1)>=1,A3-CEILING(Assumptions!$E$29/30,1)<=156),INDEX($E$2:$E$157,A3-CEILING(Assumptions!$E$29/30,1))*Assumptions!$B$29/100,0) | N3: =IF(AND(A3-CEILING(Assumptions!$E$30/30,1)>=1,A3-CEILING(Assumptions!$E$30/30,1)<=156),INDEX($E$2:$E$157,A3-CEILING(Assumptions!$E$30/30,1))*Assumptions!$B$30/100,0) | O3: =IF(AND(A3-CEILING(Assumptions!$E$31/30,1)>=1,A3-CEILING(Assumptions!$E$31/30,1)<=156),INDEX($E$2:$E$157,A3-CEILING(Assumptions!$E$31/30,1))*Assumptions!$B$31/100,0) | P3: =K3+L3+M3+N3+O3
A4: 3 | B4: 1 | C4: =Assumptions!$B$5*Assumptions!$B$32*Assumptions!$B$6*D4 | D4: =IF(A4<=3,Assumptions!$B$21,IF(A4<=6,Assumptions!$B$22,IF(A4<=12,Assumptions!$B$23,Assumptions!$B$24)))/100 | E4: =Assumptions!$B$5*Assumptions!$B$33*Assumptions!$B$6*D4 | F4: =Assumptions!$B$5*Assumptions!$B$7*Assumptions!$B$6*D4 | G4: =Assumptions!$B$8 | H4: =IF(INDEX(Assumptions!$B$35:$B$47,B4)<>"",INDEX(Assumptions!$B$35:$B$47,B4)/100*Assumptions!$B$2,IF(B4<=Assumptions!$B$17,0,IF(B4<=Assumptions!$B$17+Assumptions!$B$18,Assumptions!$B$19,Assumptions!$B$20)))/12 | I4: =IF(Assumptions!$B$12="Cash",0,IF(A4<=Assumptions!$B$15,Monthly!$S$1,0)) | J4: =E4-F4-G4-H4-I4 | K4: =IF(AND(A4-CEILING(Assumptions!$E$27/30,1)>=1,A4-CEILING(Assumptions!$E$27/30,1)<=156),INDEX($E$2:$E$157,A4-CEILING(Assumptions!$E$27/30,1))*Assumptions!$B$27/100,0) | L4: =IF(AND(A4-CEILING(Assumptions!$E$28/30,1)>=1,A4-CEILING(Assumptions!$E$28/30,1)<=156),INDEX($E$2:$E$157,A4-CEILING(Assumptions!$E$28/30,1))*Assumptions!$B$28/100,0) | M4: =IF(AND(A4-CEILING(Assumptions!$E$29/30,1)>=1,A4-CEILING(Assumptions!$E$29/30,1)<=156),INDEX($E$2:$E$157,A4-CEILING(Assumptions!$E$29/30,1))*Assumptions!$B$29/100,0) | N4: =IF(AND(A4-CEILING(Assumptions!$E$30/30,1)>=1,A4-CEILING(Assumptions!$E$30/30,1)<=156),INDEX($E$2:$E$157,A4-CEILING(Assumptions!$E$30/30,1))*Assumptions!$B$30/100,0) | O4: =IF(AND(A4-CEILING(Assumptions!$E$31/30,1)>=1,A4-CEILING(Assumptions!$E$31/30,1)<=156),INDEX($E$2:$E$157,A4-CEILING(Assumptions!$E$31/30,1))*Assumptions!$B$31/100,0) | P4: =K4+L4+M4+N4+O4
A5: 4 | B5: 1 | C5: =Assumptions!$B$5*Assumptions!$B$32*Assumptions!$B$6*D5 | D5: =IF(A5<=3,Assumptions!$B$21,IF(A5<=6,Assumptions!$B$22,IF(A5<=12,Assumptions!$B$23,Assumptions!$B$24)))/100 | E5: =Assumptions!$B$5*Assumptions!$B$33*Assumptions!$B$6*D5 | F5: =Assumptions!$B$5*Assumptions!$B$7*Assumptions!$B$6*D5 | G5: =Assumptions!$B$8 | H5: =IF(INDEX(Assumptions!$B$35:$B$47,B5)<>"",INDEX(Assumptions!$B$35:$B$47,B5)/100*Assumptions!$B$2,IF(B5<=Assumptions!$B$17,0,IF(B5<=Assumptions!$B$17+Assumptions!$B$18,Assumptions!$B$19,Assumptions!$B$20)))/12 | I5: =IF(Assumptions!$B$12="Cash",0,IF(A5<=Assumptions!$B$15,Monthly!$S$1,0)) | J5: =E5-F5-G5-H5-I5 | K5: =IF(AND(A5-CEILING(Assumptions!$E$27/30,1)>=1,A5-CEILING(Assumptions!$E$27/30,1)<=156),INDEX($E$2:$E$157,A5-CEILING(Assumptions!$E$27/30,1))*Assumptions!$B$27/100,0) | L5: =IF(AND(A5-CEILING(Assumptions!$E$28/30,1)>=1,A5-CEILING(Assumptions!$E$28/30,1)<=156),INDEX($E$2:$E$157,A5-CEILING(Assumptions!$E$28/30,1))*Assumptions!$B$28/100,0) | M5: =IF(AND(A5-CEILING(Assumptions!$E$29/30,1)>=1,A5-CEILING(Assumptions!$E$29/30,1)<=156),INDEX($E$2:$E$157,A5-CEILING(Assumptions!$E$29/30,1))*Assumptions!$B$29/100,0) | N5: =IF(AND(A5-CEILING(Assumptions!$E$30/30,1)>=1,A5-CEILING(Assumptions!$E$30/30,1)<=156),INDEX($E$2:$E$157,A5-CEILING(Assumptions!$E$30/30,1))*Assumptions!$B$30/100,0) | O5: =IF(AND(A5-CEILING(Assumptions!$E$31/30,1)>=1,A5-CEILING(Assumptions!$E$31/30,1)<=156),INDEX($E$2:$E$157,A5-CEILING(Assumptions!$E$31/30,1))*Assumptions!$B$31/100,0) | P5: =K5+L5+M5+N5+O5
A6: 5 | B6: 1 | C6: =Assumptions!$B$5*Assumptions!$B$32*Assumptions!$B$6*D6 | D6: =IF(A6<=3,Assumptions!$B$21,IF(A6<=6,Assumptions!$B$22,IF(A6<=12,Assumptions!$B$23,Assumptions!$B$24)))/100 | E6: =Assumptions!$B$5*Assumptions!$B$33*Assumptions!$B$6*D6 | F6: =Assumptions!$B$5*Assumptions!$B$7*Assumptions!$B$6*D6 | G6: =Assumptions!$B$8 | H6: =IF(INDEX(Assumptions!$B$35:$B$47,B6)<>"",INDEX(Assumptions!$B$35:$B$47,B6)/100*Assumptions!$B$2,IF(B6<=Assumptions!$B$17,0,IF(B6<=Assumptions!$B$17+Assumptions!$B$18,Assumptions!$B$19,Assumptions!$B$20)))/12 | I6: =IF(Assumptions!$B$12="Cash",0,IF(A6<=Assumptions!$B$15,Monthly!$S$1,0)) | J6: =E6-F6-G6-H6-I6 | K6: =IF(AND(A6-CEILING(Assumptions!$E$27/30,1)>=1,A6-CEILING(Assumptions!$E$27/30,1)<=156),INDEX($E$2:$E$157,A6-CEILING(Assumptions!$E$27/30,1))*Assumptions!$B$27/100,0) | L6: =IF(AND(A6-CEILING(Assumptions!$E$28/30,1)>=1,A6-CEILING(Assumptions!$E$28/30,1)<=156),INDEX($E$2:$E$157,A6-CEILING(Assumptions!$E$28/30,1))*Assumptions!$B$28/100,0) | M6: =IF(AND(A6-CEILING(Assumptions!$E$29/30,1)>=1,A6-CEILING(Assumptions!$E$29/30,1)<=156),INDEX($E$2:$E$157,A6-CEILING(Assumptions!$E$29/30,1))*Assumptions!$B$29/100,0) | N6: =IF(AND(A6-CEILING(Assumptions!$E$30/30,1)>=1,A6-CEILING(Assumptions!$E$30/30,1)<=156),INDEX($E$2:$E$157,A6-CEILING(Assumptions!$E$30/30,1))*Assumptions!$B$30/100,0) | O6: =IF(AND(A6-CEILING(Assumptions!$E$31/30,1)>=1,A6-CEILING(Assumptions!$E$31/30,1)<=156),INDEX($E$2:$E$157,A6-CEILING(Assumptions!$E$31/30,1))*Assumptions!$B$31/100,0) | P6: =K6+L6+M6+N6+O6
A7: 6 | B7: 1 | C7: =Assumptions!$B$5*Assumptions!$B$32*Assumptions!$B$6*D7 | D7: =IF(A7<=3,Assumptions!$B$21,IF(A7<=6,Assumptions!$B$22,IF(A7<=12,Assumptions!$B$23,Assumptions!$B$24)))/100 | E7: =Assumptions!$B$5*Assumptions!$B$33*Assumptions!$B$6*D7 | F7: =Assumptions!$B$5*Assumptions!$B$7*Assumptions!$B$6*D7 | G7: =Assumptions!$B$8 | H7: =IF(INDEX(Assumptions!$B$35:$B$47,B7)<>"",INDEX(Assumptions!$B$35:$B$47,B7)/100*Assumptions!$B$2,IF(B7<=Assumptions!$B$17,0,IF(B7<=Assumptions!$B$17+Assumptions!$B$18,Assumptions!$B$19,Assumptions!$B$20)))/12 | I7: =IF(Assumptions!$B$12="Cash",0,IF(A7<=Assumptions!$B$15,Monthly!$S$1,0)) | J7: =E7-F7-G7-H7-I7 | K7: =IF(AND(A7-CEILING(Assumptions!$E$27/30,1)>=1,A7-CEILING(Assumptions!$E$27/30,1)<=156),INDEX($E$2:$E$157,A7-CEILING(Assumptions!$E$27/30,1))*Assumptions!$B$27/100,0) | L7: =IF(AND(A7-CEILING(Assumptions!$E$28/30,1)>=1,A7-CEILING(Assumptions!$E$28/30,1)<=156),INDEX($E$2:$E$157,A7-CEILING(Assumptions!$E$28/30,1))*Assumptions!$B$28/100,0) | M7: =IF(AND(A7-CEILING(Assumptions!$E$29/30,1)>=1,A7-CEILING(Assumptions!$E$29/30,1)<=156),INDEX($E$2:$E$157,A7-CEILING(Assumptions!$E$29/30,1))*Assumptions!$B$29/100,0) | N7: =IF(AND(A7-CEILING(Assumptions!$E$30/30,1)>=1,A7-CEILING(Assumptions!$E$30/30,1)<=156),INDEX($E$2:$E$157,A7-CEILING(Assumptions!$E$30/30,1))*Assumptions!$B$30/100,0) | O7: =IF(AND(A7-CEILING(Assumptions!$E$31/30,1)>=1,A7-CEILING(Assumptions!$E$31/30,1)<=156),INDEX($E$2:$E$157,A7-CEILING(Assumptions!$E$31/30,1))*Assumptions!$B$31/100,0) | P7: =K7+L7+M7+N7+O7
A8: 7 | B8: 1 | C8: =Assumptions!$B$5*Assumptions!$B$32*Assumptions!$B$6*D8 | D8: =IF(A8<=3,Assumptions!$B$21,IF(A8<=6,Assumptions!$B$22,IF(A8<=12,Assumptions!$B$23,Assumptions!$B$24)))/100 | E8: =Assumptions!$B$5*Assumptions!$B$33*Assumptions!$B$6*D8 | F8: =Assumptions!$B$5*Assumptions!$B$7*Assumptions!$B$6*D8 | G8: =Assumptions!$B$8 | H8: =IF(INDEX(Assumptions!$B$35:$B$47,B8)<>"",INDEX(Assumptions!$B$35:$B$47,B8)/100*Assumptions!$B$2,IF(B8<=Assumptions!$B$17,0,IF(B8<=Assumptions!$B$17+Assumptions!$B$18,Assumptions!$B$19,Assumptions!$B$20)))/12 | I8: =IF(Assumptions!$B$12="Cash",0,IF(A8<=Assumptions!$B$15,Monthly!$S$1,0)) | J8: =E8-F8-G8-H8-I8 | K8: =IF(AND(A8-CEILING(Assumptions!$E$27/30,1)>=1,A8-CEILING(Assumptions!$E$27/30,1)<=156),INDEX($E$2:$E$157,A8-CEILING(Assumptions!$E$27/30,1))*Assumptions!$B$27/100,0) | L8: =IF(AND(A8-CEILING(Assumptions!$E$28/30,1)>=1,A8-CEILING(Assumptions!$E$28/30,1)<=156),INDEX($E$2:$E$157,A8-CEILING(Assumptions!$E$28/30,1))*Assumptions!$B$28/100,0) | M8: =IF(AND(A8-CEILING(Assumptions!$E$29/30,1)>=1,A8-CEILING(Assumptions!$E$29/30,1)<=156),INDEX($E$2:$E$157,A8-CEILING(Assumptions!$E$29/30,1))*Assumptions!$B$29/100,0) | N8: =IF(AND(A8-CEILING(Assumptions!$E$30/30,1)>=1,A8-CEILING(Assumptions!$E$30/30,1)<=156),INDEX($E$2:$E$157,A8-CEILING(Assumptions!$E$30/30,1))*Assumptions!$B$30/100,0) | O8: =IF(AND(A8-CEILING(Assumptions!$E$31/30,1)>=1,A8-CEILING(Assumptions!$E$31/30,1)<=156),INDEX($E$2:$E$157,A8-CEILING(Assumptions!$E$31/30,1))*Assumptions!$B$31/100,0) | P8: =K8+L8+M8+N8+O8
A9: 8 | B9: 1 | C9: =Assumptions!$B$5*Assumptions!$B$32*Assumptions!$B$6*D9 | D9: =IF(A9<=3,Assumptions!$B$21,IF(A9<=6,Assumptions!$B$22,IF(A9<=12,Assumptions!$B$23,Assumptions!$B$24)))/100 | E9: =Assumptions!$B$5*Assumptions!$B$33*Assumptions!$B$6*D9 | F9: =Assumptions!$B$5*Assumptions!$B$7*Assumptions!$B$6*D9 | G9: =Assumptions!$B$8 | H9: =IF(INDEX(Assumptions!$B$35:$B$47,B9)<>"",INDEX(Assumptions!$B$35:$B$47,B9)/100*Assumptions!$B$2,IF(B9<=Assumptions!$B$17,0,IF(B9<=Assumptions!$B$17+Assumptions!$B$18,Assumptions!$B$19,Assumptions!$B$20)))/12 | I9: =IF(Assumptions!$B$12="Cash",0,IF(A9<=Assumptions!$B$15,Monthly!$S$1,0)) | J9: =E9-F9-G9-H9-I9 | K9: =IF(AND(A9-CEILING(Assumptions!$E$27/30,1)>=1,A9-CEILING(Assumptions!$E$27/30,1)<=156),INDEX($E$2:$E$157,A9-CEILING(Assumptions!$E$27/30,1))*Assumptions!$B$27/100,0) | L9: =IF(AND(A9-CEILING(Assumptions!$E$28/30,1)>=1,A9-CEILING(Assumptions!$E$28/30,1)<=156),INDEX($E$2:$E$157,A9-CEILING(Assumptions!$E$28/30,1))*Assumptions!$B$28/100,0) | M9: =IF(AND(A9-CEILING(Assumptions!$E$29/30,1)>=1,A9-CEILING(Assumptions!$E$29/30,1)<=156),INDEX($E$2:$E$157,A9-CEILING(Assumptions!$E$29/30,1))*Assumptions!$B$29/100,0) | N9: =IF(AND(A9-CEILING(Assumptions!$E$30/30,1)>=1,A9-CEILING(Assumptions!$E$30/30,1)<=156),INDEX($E$2:$E$157,A9-CEILING(Assumptions!$E$30/30,1))*Assumptions!$B$30/100,0) | O9: =IF(AND(A9-CEILING(Assumptions!$E$31/30,1)>=1,A9-CEILING(Assumptions!$E$31/30,1)<=156),INDEX($E$2:$E$157,A9-CEILING(Assumptions!$E$31/30,1))*Assumptions!$B$31/100,0) | P9: =K9+L9+M9+N9+O9
A10: 9 | B10: 1 | C10: =Assumptions!$B$5*Assumptions!$B$32*Assumptions!$B$6*D10 | D10: =IF(A10<=3,Assumptions!$B$21,IF(A10<=6,Assumptions!$B$22,IF(A10<=12,Assumptions!$B$23,Assumptions!$B$24)))/100 | E10: =Assumptions!$B$5*Assumptions!$B$33*Assumptions!$B$6*D10 | F10: =Assumptions!$B$5*Assumptions!$B$7*Assumptions!$B$6*D10 | G10: =Assumptions!$B$8 | H10: =IF(INDEX(Assumptions!$B$35:$B$47,B10)<>"",INDEX(Assumptions!$B$35:$B$47,B10)/100*Assumptions!$B$2,IF(B10<=Assumptions!$B$17,0,IF(B10<=Assumptions!$B$17+Assumptions!$B$18,Assumptions!$B$19,Assumptions!$B$20)))/12 | I10: =IF(Assumptions!$B$12="Cash",0,IF(A10<=Assumptions!$B$15,Monthly!$S$1,0)) | J10: =E10-F10-G10-H10-I10 | K10: =IF(AND(A10-CEILING(Assumptions!$E$27/30,1)>=1,A10-CEILING(Assumptions!$E$27/30,1)<=156),INDEX($E$2:$E$157,A10-CEILING(Assumptions!$E$27/30,1))*Assumptions!$B$27/100,0) | L10: =IF(AND(A10-CEILING(Assumptions!$E$28/30,1)>=1,A10-CEILING(Assumptions!$E$28/30,1)<=156),INDEX($E$2:$E$157,A10-CEILING(Assumptions!$E$28/30,1))*Assumptions!$B$28/100,0) | M10: =IF(AND(A10-CEILING(Assumptions!$E$29/30,1)>=1,A10-CEILING(Assumptions!$E$29/30,1)<=156),INDEX($E$2:$E$157,A10-CEILING(Assumptions!$E$29/30,1))*Assumptions!$B$29/100,0) | N10: =IF(AND(A10-CEILING(Assumptions!$E$30/30,1)>=1,A10-CEILING(Assumptions!$E$30/30,1)<=156),INDEX($E$2:$E$157,A10-CEILING(Assumptions!$E$30/30,1))*Assumptions!$B$30/100,0) | O10: =IF(AND(A10-CEILING(Assumptions!$E$31/30,1)>=1,A10-CEILING(Assumptions!$E$31/30,1)<=156),INDEX($E$2:$E$157,A10-CEILING(Assumptions!$E$31/30,1))*Assumptions!$B$31/100,0) | P10: =K10+L10+M10+N10+O10
A11: 10 | B11: 1 | C11: =Assumptions!$B$5*Assumptions!$B$32*Assumptions!$B$6*D11 | D11: =IF(A11<=3,Assumptions!$B$21,IF(A11<=6,Assumptions!$B$22,IF(A11<=12,Assumptions!$B$23,Assumptions!$B$24)))/100 | E11: =Assumptions!$B$5*Assumptions!$B$33*Assumptions!$B$6*D11 | F11: =Assumptions!$B$5*Assumptions!$B$7*Assumptions!$B$6*D11 | G11: =Assumptions!$B$8 | H11: =IF(INDEX(Assumptions!$B$35:$B$47,B11)<>"",INDEX(Assumptions!$B$35:$B$47,B11)/100*Assumptions!$B$2,IF(B11<=Assumptions!$B$17,0,IF(B11<=Assumptions!$B$17+Assumptions!$B$18,Assumptions!$B$19,Assumptions!$B$20)))/12 | I11: =IF(Assumptions!$B$12="Cash",0,IF(A11<=Assumptions!$B$15,Monthly!$S$1,0)) | J11: =E11-F11-G11-H11-I11 | K11: =IF(AND(A11-CEILING(Assumptions!$E$27/30,1)>=1,A11-CEILING(Assumptions!$E$27/30,1)<=156),INDEX($E$2:$E$157,A11-CEILING(Assumptions!$E$27/30,1))*Assumptions!$B$27/100,0) | L11: =IF(AND(A11-CEILING(Assumptions!$E$28/30,1)>=1,A11-CEILING(Assumptions!$E$28/30,1)<=156),INDEX($E$2:$E$157,A11-CEILING(Assumptions!$E$28/30,1))*Assumptions!$B$28/100,0) | M11: =IF(AND(A11-CEILING(Assumptions!$E$29/30,1)>=1,A11-CEILING(Assumptions!$E$29/30,1)<=156),INDEX($E$2:$E$157,A11-CEILING(Assumptions!$E$29/30,1))*Assumptions!$B$29/100,0) | N11: =IF(AND(A11-CEILING(Assumptions!$E$30/30,1)>=1,A11-CEILING(Assumptions!$E$30/30,1)<=156),INDEX($E$2:$E$157,A11-CEILING(Assumptions!$E$30/30,1))*Assumptions!$B$30/100,0) | O11: =IF(AND(A11-CEILING(Assumptions!$E$31/30,1)>=1,A11-CEILING(Assumptions!$E$31/30,1)<=156),INDEX($E$2:$E$157,A11-CEILING(Assumptions!$E$31/30,1))*Assumptions!$B$31/100,0) | P11: =K11+L11+M11+N11+O11
A12: 11 | B12: 1 | C12: =Assumptions!$B$5*Assumptions!$B$32*Assumptions!$B$6*D12 | D12: =IF(A12<=3,Assumptions!$B$21,IF(A12<=6,Assumptions!$B$22,IF(A12<=12,Assumptions!$B$23,Assumptions!$B$24)))/100 | E12: =Assumptions!$B$5*Assumptions!$B$33*Assumptions!$B$6*D12 | F12: =Assumptions!$B$5*Assumptions!$B$7*Assumptions!$B$6*D12 | G12: =Assumptions!$B$8 | H12: =IF(INDEX(Assumptions!$B$35:$B$47,B12)<>"",INDEX(Assumptions!$B$35:$B$47,B12)/100*Assumptions!$B$2,IF(B12<=Assumptions!$B$17,0,IF(B12<=Assumptions!$B$17+Assumptions!$B$18,Assumptions!$B$19,Assumptions!$B$20)))/12 | I12: =IF(Assumptions!$B$12="Cash",0,IF(A12<=Assumptions!$B$15,Monthly!$S$1,0)) | J12: =E12-F12-G12-H12-I12 | K12: =IF(AND(A12-CEILING(Assumptions!$E$27/30,1)>=1,A12-CEILING(Assumptions!$E$27/30,1)<=156),INDEX($E$2:$E$157,A12-CEILING(Assumptions!$E$27/30,1))*Assumptions!$B$27/100,0) | L12: =IF(AND(A12-CEILING(Assumptions!$E$28/30,1)>=1,A12-CEILING(Assumptions!$E$28/30,1)<=156),INDEX($E$2:$E$157,A12-CEILING(Assumptions!$E$28/30,1))*Assumptions!$B$28/100,0) | M12: =IF(AND(A12-CEILING(Assumptions!$E$29/30,1)>=1,A12-CEILING(Assumptions!$E$29/30,1)<=156),INDEX($E$2:$E$157,A12-CEILING(Assumptions!$E$29/30,1))*Assumptions!$B$29/100,0) | N12: =IF(AND(A12-CEILING(Assumptions!$E$30/30,1)>=1,A12-CEILING(Assumptions!$E$30/30,1)<=156),INDEX($E$2:$E$157,A12-CEILING(Assumptions!$E$30/30,1))*Assumptions!$B$30/100,0) | O12: =IF(AND(A12-CEILING(Assumptions!$E$31/30,1)>=1,A12-CEILING(Assumptions!$E$31/30,1)<=156),INDEX($E$2:$E$157,A12-CEILING(Assumptions!$E$31/30,1))*Assumptions!$B$31/100,0) | P12: =K12+L12+M12+N12+O12
A13: 12 | B13: 1 | C13: =Assumptions!$B$5*Assumptions!$B$32*Assumptions!$B$6*D13 | D13: =IF(A13<=3,Assumptions!$B$21,IF(A13<=6,Assumptions!$B$22,IF(A13<=12,Assumptions!$B$23,Assumptions!$B$24)))/100 | E13: =Assumptions!$B$5*Assumptions!$B$33*Assumptions!$B$6*D13 | F13: =Assumptions!$B$5*Assumptions!$B$7*Assumptions!$B$6*D13 | G13: =Assumptions!$B$8 | H13: =IF(INDEX(Assumptions!$B$35:$B$47,B13)<>"",INDEX(Assumptions!$B$35:$B$47,B13)/100*Assumptions!$B$2,IF(B13<=Assumptions!$B$17,0,IF(B13<=Assumptions!$B$17+Assumptions!$B$18,Assumptions!$B$19,Assumptions!$B$20)))/12 | I13: =IF(Assumptions!$B$12="Cash",0,IF(A13<=Assumptions!$B$15,Monthly!$S$1,0)) | J13: =E13-F13-G13-H13-I13 | K13: =IF(AND(A13-CEILING(Assumptions!$E$27/30,1)>=1,A13-CEILING(Assumptions!$E$27/30,1)<=156),INDEX($E$2:$E$157,A13-CEILING(Assumptions!$E$27/30,1))*Assumptions!$B$27/100,0) | L13: =IF(AND(A13-CEILING(Assumptions!$E$28/30,1)>=1,A13-CEILING(Assumptions!$E$28/30,1)<=156),INDEX($E$2:$E$157,A13-CEILING(Assumptions!$E$28/30,1))*Assumptions!$B$28/100,0) | M13: =IF(AND(A13-CEILING(Assumptions!$E$29/30,1)>=1,A13-CEILING(Assumptions!$E$29/30,1)<=156),INDEX($E$2:$E$157,A13-CEILING(Assumptions!$E$29/30,1))*Assumptions!$B$29/100,0) | N13: =IF(AND(A13-CEILING(Assumptions!$E$30/30,1)>=1,A13-CEILING(Assumptions!$E$30/30,1)<=156),INDEX($E$2:$E$157,A13-CEILING(Assumptions!$E$30/30,1))*Assumptions!$B$30/100,0) | O13: =IF(AND(A13-CEILING(Assumptions!$E$31/30,1)>=1,A13-CEILING(Assumptions!$E$31/30,1)<=156),INDEX($E$2:$E$157,A13-CEILING(Assumptions!$E$31/30,1))*Assumptions!$B$31/100,0) | P13: =K13+L13+M13+N13+O13
... A157: 156 | B157: 13 | C157: =Assumptions!$B$5*Assumptions!$B$32*Assumptions!$B$6*D157 | D157: =IF(A157<=3,Assumptions!$B$21,IF(A157<=6,Assumptions!$B$22,IF(A157<=12,Assumptions!$B$23,Assumptions!$B$24)))/100 | E157: =Assumptions!$B$5*Assumptions!$B$33*Assumptions!$B$6*D157 | F157: =Assumptions!$B$5*Assumptions!$B$7*Assumptions!$B$6*D157 | G157: =Assumptions!$B$8 | H157: =IF(INDEX(Assumptions!$B$35:$B$47,B157)<>"",INDEX(Assumptions!$B$35:$B$47,B157)/100*Assumptions!$B$2,IF(B157<=Assumptions!$B$17,0,IF(B157<=Assumptions!$B$17+Assumptions!$B$18,Assumptions!$B$19,Assumptions!$B$20)))/12 | I157: =IF(Assumptions!$B$12="Cash",0,IF(A157<=Assumptions!$B$15,Monthly!$S$1,0)) | J157: =E157-F157-G157-H157-I157 | K157: =IF(AND(A157-CEILING(Assumptions!$E$27/30,1)>=1,A157-CEILING(Assumptions!$E$27/30,1)<=156),INDEX($E$2:$E$157,A157-CEILING(Assumptions!$E$27/30,1))*Assumptions!$B$27/100,0) | L157: =IF(AND(A157-CEILING(Assumptions!$E$28/30,1)>=1,A157-CEILING(Assumptions!$E$28/30,1)<=156),INDEX($E$2:$E$157,A157-CEILING(Assumptions!$E$28/30,1))*Assumptions!$B$28/100,0) | M157: =IF(AND(A157-CEILING(Assumptions!$E$29/30,1)>=1,A157-CEILING(Assumptions!$E$29/30,1)<=156),INDEX($E$2:$E$157,A157-CEILING(Assumptions!$E$29/30,1))*Assumptions!$B$29/100,0) | N157: =IF(AND(A157-CEILING(Assumptions!$E$30/30,1)>=1,A157-CEILING(Assumptions!$E$30/30,1)<=156),INDEX($E$2:$E$157,A157-CEILING(Assumptions!$E$30/30,1))*Assumptions!$B$30/100,0) | O157: =IF(AND(A157-CEILING(Assumptions!$E$31/30,1)>=1,A157-CEILING(Assumptions!$E$31/30,1)<=156),INDEX($E$2:$E$157,A157-CEILING(Assumptions!$E$31/30,1))*Assumptions!$B$31/100,0) | P157: =K157+L157+M157+N157+O157
A158: 157 | K158: =IF(AND(A158-CEILING(Assumptions!$E$27/30,1)>=1,A158-CEILING(Assumptions!$E$27/30,1)<=156),INDEX($E$2:$E$157,A158-CEILING(Assumptions!$E$27/30,1))*Assumptions!$B$27/100,0) | L158: =IF(AND(A158-CEILING(Assumptions!$E$28/30,1)>=1,A158-CEILING(Assumptions!$E$28/30,1)<=156),INDEX($E$2:$E$157,A158-CEILING(Assumptions!$E$28/30,1))*Assumptions!$B$28/100,0) | M158: =IF(AND(A158-CEILING(Assumptions!$E$29/30,1)>=1,A158-CEILING(Assumptions!$E$29/30,1)<=156),INDEX($E$2:$E$157,A158-CEILING(Assumptions!$E$29/30,1))*Assumptions!$B$29/100,0) | N158: =IF(AND(A158-CEILING(Assumptions!$E$30/30,1)>=1,A158-CEILING(Assumptions!$E$30/30,1)<=156),INDEX($E$2:$E$157,A158-CEILING(Assumptions!$E$30/30,1))*Assumptions!$B$30/100,0) | O158: =IF(AND(A158-CEILING(Assumptions!$E$31/30,1)>=1,A158-CEILING(Assumptions!$E$31/30,1)<=156),INDEX($E$2:$E$157,A158-CEILING(Assumptions!$E$31/30,1))*Assumptions!$B$31/100,0) | P158: =K158+L158+M158+N158+O158
A159: 158 | K159: =IF(AND(A159-CEILING(Assumptions!$E$27/30,1)>=1,A159-CEILING(Assumptions!$E$27/30,1)<=156),INDEX($E$2:$E$157,A159-CEILING(Assumptions!$E$27/30,1))*Assumptions!$B$27/100,0) | L159: =IF(AND(A159-CEILING(Assumptions!$E$28/30,1)>=1,A159-CEILING(Assumptions!$E$28/30,1)<=156),INDEX($E$2:$E$157,A159-CEILING(Assumptions!$E$28/30,1))*Assumptions!$B$28/100,0) | M159: =IF(AND(A159-CEILING(Assumptions!$E$29/30,1)>=1,A159-CEILING(Assumptions!$E$29/30,1)<=156),INDEX($E$2:$E$157,A159-CEILING(Assumptions!$E$29/30,1))*Assumptions!$B$29/100,0) | N159: =IF(AND(A159-CEILING(Assumptions!$E$30/30,1)>=1,A159-CEILING(Assumptions!$E$30/30,1)<=156),INDEX($E$2:$E$157,A159-CEILING(Assumptions!$E$30/30,1))*Assumptions!$B$30/100,0) | O159: =IF(AND(A159-CEILING(Assumptions!$E$31/30,1)>=1,A159-CEILING(Assumptions!$E$31/30,1)<=156),INDEX($E$2:$E$157,A159-CEILING(Assumptions!$E$31/30,1))*Assumptions!$B$31/100,0) | P159: =K159+L159+M159+N159+O159

Sheet Annual Summary
A1: Year | B1: Billed revenue | C1: Realized revenue | D1: Operating cost | E1: EMI / lease | F1: Net cash flow after financing | G1: Cumulative cash position
A2: 1 | B2: =SUM(Monthly!$C$2:$C$13) | C2: =SUM(Monthly!$E$2:$E$13) | D2: =SUM(Monthly!$F$2:$F$13)+SUM(Monthly!$G$2:$G$13)+SUM(Monthly!$H$2:$H$13) | E2: =SUM(Monthly!$I$2:$I$13) | F2: =SUM(Monthly!$J$2:$J$13) | G2: =F2-Assumptions!$B$4
A3: 2 | B3: =SUM(Monthly!$C$14:$C$25) | C3: =SUM(Monthly!$E$14:$E$25) | D3: =SUM(Monthly!$F$14:$F$25)+SUM(Monthly!$G$14:$G$25)+SUM(Monthly!$H$14:$H$25) | E3: =SUM(Monthly!$I$14:$I$25) | F3: =SUM(Monthly!$J$14:$J$25) | G3: =G2+F3
A4: 3 | B4: =SUM(Monthly!$C$26:$C$37) | C4: =SUM(Monthly!$E$26:$E$37) | D4: =SUM(Monthly!$F$26:$F$37)+SUM(Monthly!$G$26:$G$37)+SUM(Monthly!$H$26:$H$37) | E4: =SUM(Monthly!$I$26:$I$37) | F4: =SUM(Monthly!$J$26:$J$37) | G4: =G3+F4
A5: 4 | B5: =SUM(Monthly!$C$38:$C$49) | C5: =SUM(Monthly!$E$38:$E$49) | D5: =SUM(Monthly!$F$38:$F$49)+SUM(Monthly!$G$38:$G$49)+SUM(Monthly!$H$38:$H$49) | E5: =SUM(Monthly!$I$38:$I$49) | F5: =SUM(Monthly!$J$38:$J$49) | G5: =G4+F5
A6: 5 | B6: =SUM(Monthly!$C$50:$C$61) | C6: =SUM(Monthly!$E$50:$E$61) | D6: =SUM(Monthly!$F$50:$F$61)+SUM(Monthly!$G$50:$G$61)+SUM(Monthly!$H$50:$H$61) | E6: =SUM(Monthly!$I$50:$I$61) | F6: =SUM(Monthly!$J$50:$J$61) | G6: =G5+F6
A7: 6 | B7: =SUM(Monthly!$C$62:$C$73) | C7: =SUM(Monthly!$E$62:$E$73) | D7: =SUM(Monthly!$F$62:$F$73)+SUM(Monthly!$G$62:$G$73)+SUM(Monthly!$H$62:$H$73) | E7: =SUM(Monthly!$I$62:$I$73) | F7: =SUM(Monthly!$J$62:$J$73) | G7: =G6+F7
A8: 7 | B8: =SUM(Monthly!$C$74:$C$85) | C8: =SUM(Monthly!$E$74:$E$85) | D8: =SUM(Monthly!$F$74:$F$85)+SUM(Monthly!$G$74:$G$85)+SUM(Monthly!$H$74:$H$85) | E8: =SUM(Monthly!$I$74:$I$85) | F8: =SUM(Monthly!$J$74:$J$85) | G8: =G7+F8
A9: 8 | B9: =SUM(Monthly!$C$86:$C$97) | C9: =SUM(Monthly!$E$86:$E$97) | D9: =SUM(Monthly!$F$86:$F$97)+SUM(Monthly!$G$86:$G$97)+SUM(Monthly!$H$86:$H$97) | E9: =SUM(Monthly!$I$86:$I$97) | F9: =SUM(Monthly!$J$86:$J$97) | G9: =G8+F9
A10: 9 | B10: =SUM(Monthly!$C$98:$C$109) | C10: =SUM(Monthly!$E$98:$E$109) | D10: =SUM(Monthly!$F$98:$F$109)+SUM(Monthly!$G$98:$G$109)+SUM(Monthly!$H$98:$H$109) | E10: =SUM(Monthly!$I$98:$I$109) | F10: =SUM(Monthly!$J$98:$J$109) | G10: =G9+F10
A11: 10 | B11: =SUM(Monthly!$C$110:$C$121) | C11: =SUM(Monthly!$E$110:$E$121) | D11: =SUM(Monthly!$F$110:$F$121)+SUM(Monthly!$G$110:$G$121)+SUM(Monthly!$H$110:$H$121) | E11: =SUM(Monthly!$I$110:$I$121) | F11: =SUM(Monthly!$J$110:$J$121) | G11: =G10+F11
A12: 11 | B12: =SUM(Monthly!$C$122:$C$133) | C12: =SUM(Monthly!$E$122:$E$133) | D12: =SUM(Monthly!$F$122:$F$133)+SUM(Monthly!$G$122:$G$133)+SUM(Monthly!$H$122:$H$133) | E12: =SUM(Monthly!$I$122:$I$133) | F12: =SUM(Monthly!$J$122:$J$133) | G12: =G11+F12
A13: 12 | B13: =SUM(Monthly!$C$134:$C$145) | C13: =SUM(Monthly!$E$134:$E$145) | D13: =SUM(Monthly!$F$134:$F$145)+SUM(Monthly!$G$134:$G$145)+SUM(Monthly!$H$134:$H$145) | E13: =SUM(Monthly!$I$134:$I$145) | F13: =SUM(Monthly!$J$134:$J$145) | G13: =G12+F13
A14: 13 | B14: =SUM(Monthly!$C$146:$C$157) | C14: =SUM(Monthly!$E$146:$E$157) | D14: =SUM(Monthly!$F$146:$F$157)+SUM(Monthly!$G$146:$G$157)+SUM(Monthly!$H$146:$H$157) | E14: =SUM(Monthly!$I$146:$I$157) | F14: =SUM(Monthly!$J$146:$J$157) | G14: =G13+F14
A16: NPV | B16: =NPV(Assumptions!$B$10/100,F2:F14)-Assumptions!$B$4
A17: IRR | B17: =IRR($H$17:$U$17) | H17: =-Assumptions!$B$4 | I17: =F2 | J17: =F3 | K17: =F4 | L17: =F5 | M17: =F6 | N17: =F7 | O17: =F8 | P17: =F9 | Q17: =F10 | R17: =F11 | S17: =F12 | T17: =F13 | U17: =F14

Sheet Break-even Analysis
A1: Contribution per use | B1: =Assumptions!$B$33-Assumptions!$B$7
A2: Expected usage per day | B2: =Assumptions!$B$5
A3: Break-even usage per day | B3: =IF($B$1<=0,"Undefined — contribution margin is zero or negative",Assumptions!$B$8/$B$1/Assumptions!$B$6)
A4: Clears break-even | B4: =IF(ISNUMBER($B$3),$B$2>=$B$3,"N/A")

Sheet Maintenance Schedule
A1: Year | B1: Coverage | C1: Annual cost
A2: 1 | B2: =IF(Assumptions!$B$35<>"","Override",IF(1<=Assumptions!$B$17,"Warranty",IF(1<=Assumptions!$B$17+Assumptions!$B$18,"CMC","AMC"))) | C2: =IF(Assumptions!$B$35<>"",Assumptions!$B$35/100*Assumptions!$B$2,IF(1<=Assumptions!$B$17,0,IF(1<=Assumptions!$B$17+Assumptions!$B$18,Assumptions!$B$19,Assumptions!$B$20)))
A3: 2 | B3: =IF(Assumptions!$B$36<>"","Override",IF(2<=Assumptions!$B$17,"Warranty",IF(2<=Assumptions!$B$17+Assumptions!$B$18,"CMC","AMC"))) | C3: =IF(Assumptions!$B$36<>"",Assumptions!$B$36/100*Assumptions!$B$2,IF(2<=Assumptions!$B$17,0,IF(2<=Assumptions!$B$17+Assumptions!$B$18,Assumptions!$B$19,Assumptions!$B$20)))
A4: 3 | B4: =IF(Assumptions!$B$37<>"","Override",IF(3<=Assumptions!$B$17,"Warranty",IF(3<=Assumptions!$B$17+Assumptions!$B$18,"CMC","AMC"))) | C4: =IF(Assumptions!$B$37<>"",Assumptions!$B$37/100*Assumptions!$B$2,IF(3<=Assumptions!$B$17,0,IF(3<=Assumptions!$B$17+Assumptions!$B$18,Assumptions!$B$19,Assumptions!$B$20)))
A5: 4 | B5: =IF(Assumptions!$B$38<>"","Override",IF(4<=Assumptions!$B$17,"Warranty",IF(4<=Assumptions!$B$17+Assumptions!$B$18,"CMC","AMC"))) | C5: =IF(Assumptions!$B$38<>"",Assumptions!$B$38/100*Assumptions!$B$2,IF(4<=Assumptions!$B$17,0,IF(4<=Assumptions!$B$17+Assumptions!$B$18,Assumptions!$B$19,Assumptions!$B$20)))
A6: 5 | B6: =IF(Assumptions!$B$39<>"","Override",IF(5<=Assumptions!$B$17,"Warranty",IF(5<=Assumptions!$B$17+Assumptions!$B$18,"CMC","AMC"))) | C6: =IF(Assumptions!$B$39<>"",Assumptions!$B$39/100*Assumptions!$B$2,IF(5<=Assumptions!$B$17,0,IF(5<=Assumptions!$B$17+Assumptions!$B$18,Assumptions!$B$19,Assumptions!$B$20)))
A7: 6 | B7: =IF(Assumptions!$B$40<>"","Override",IF(6<=Assumptions!$B$17,"Warranty",IF(6<=Assumptions!$B$17+Assumptions!$B$18,"CMC","AMC"))) | C7: =IF(Assumptions!$B$40<>"",Assumptions!$B$40/100*Assumptions!$B$2,IF(6<=Assumptions!$B$17,0,IF(6<=Assumptions!$B$17+Assumptions!$B$18,Assumptions!$B$19,Assumptions!$B$20)))
A8: 7 | B8: =IF(Assumptions!$B$41<>"","Override",IF(7<=Assumptions!$B$17,"Warranty",IF(7<=Assumptions!$B$17+Assumptions!$B$18,"CMC","AMC"))) | C8: =IF(Assumptions!$B$41<>"",Assumptions!$B$41/100*Assumptions!$B$2,IF(7<=Assumptions!$B$17,0,IF(7<=Assumptions!$B$17+Assumptions!$B$18,Assumptions!$B$19,Assumptions!$B$20)))
A9: 8 | B9: =IF(Assumptions!$B$42<>"","Override",IF(8<=Assumptions!$B$17,"Warranty",IF(8<=Assumptions!$B$17+Assumptions!$B$18,"CMC","AMC"))) | C9: =IF(Assumptions!$B$42<>"",Assumptions!$B$42/100*Assumptions!$B$2,IF(8<=Assumptions!$B$17,0,IF(8<=Assumptions!$B$17+Assumptions!$B$18,Assumptions!$B$19,Assumptions!$B$20)))
A10: 9 | B10: =IF(Assumptions!$B$43<>"","Override",IF(9<=Assumptions!$B$17,"Warranty",IF(9<=Assumptions!$B$17+Assumptions!$B$18,"CMC","AMC"))) | C10: =IF(Assumptions!$B$43<>"",Assumptions!$B$43/100*Assumptions!$B$2,IF(9<=Assumptions!$B$17,0,IF(9<=Assumptions!$B$17+Assumptions!$B$18,Assumptions!$B$19,Assumptions!$B$20)))
A11: 10 | B11: =IF(Assumptions!$B$44<>"","Override",IF(10<=Assumptions!$B$17,"Warranty",IF(10<=Assumptions!$B$17+Assumptions!$B$18,"CMC","AMC"))) | C11: =IF(Assumptions!$B$44<>"",Assumptions!$B$44/100*Assumptions!$B$2,IF(10<=Assumptions!$B$17,0,IF(10<=Assumptions!$B$17+Assumptions!$B$18,Assumptions!$B$19,Assumptions!$B$20)))
A12: 11 | B12: =IF(Assumptions!$B$45<>"","Override",IF(11<=Assumptions!$B$17,"Warranty",IF(11<=Assumptions!$B$17+Assumptions!$B$18,"CMC","AMC"))) | C12: =IF(Assumptions!$B$45<>"",Assumptions!$B$45/100*Assumptions!$B$2,IF(11<=Assumptions!$B$17,0,IF(11<=Assumptions!$B$17+Assumptions!$B$18,Assumptions!$B$19,Assumptions!$B$20)))
A13: 12 | B13: =IF(Assumptions!$B$46<>"","Override",IF(12<=Assumptions!$B$17,"Warranty",IF(12<=Assumptions!$B$17+Assumptions!$B$18,"CMC","AMC"))) | C13: =IF(Assumptions!$B$46<>"",Assumptions!$B$46/100*Assumptions!$B$2,IF(12<=Assumptions!$B$17,0,IF(12<=Assumptions!$B$17+Assumptions!$B$18,Assumptions!$B$19,Assumptions!$B$20)))
A14: 13 | B14: =IF(Assumptions!$B$47<>"","Override",IF(13<=Assumptions!$B$17,"Warranty",IF(13<=Assumptions!$B$17+Assumptions!$B$18,"CMC","AMC"))) | C14: =IF(Assumptions!$B$47<>"",Assumptions!$B$47/100*Assumptions!$B$2,IF(13<=Assumptions!$B$17,0,IF(13<=Assumptions!$B$17+Assumptions!$B$18,Assumptions!$B$19,Assumptions!$B$20)))

Sheet Charts
A1: Year | B1: Cumulative cash position | D1: Expected usage per day | E1: Break-even usage per day
A2: 1 | B2: ='Annual Summary'!G2 | D2: ='Break-even Analysis'!B2 | E2: ='Break-even Analysis'!B3
A3: 2 | B3: ='Annual Summary'!G3
A4: 3 | B4: ='Annual Summary'!G4
A5: 4 | B5: ='Annual Summary'!G5
A6: 5 | B6: ='Annual Summary'!G6
A7: 6 | B7: ='Annual Summary'!G7
A8: 7 | B8: ='Annual Summary'!G8
A9: 8 | B9: ='Annual Summary'!G9
A10: 9 | B10: ='Annual Summary'!G10
A11: 10 | B11: ='Annual Summary'!G11
A12: 11 | B12: ='Annual Summary'!G12
A13: 12 | B13: ='Annual Summary'!G13
A14: 13 | B14: ='Annual Summary'!G14

Sheet Formula Notes
A1: Formula | B1: Description
A2: Billed monthly revenue | B2: Usage per day x Average billed revenue per use x Working days per month x Ramp % (same ramp as realized revenue)
A3: Realized revenue per use | B3: Volume-weighted average across payer types of (share % x tariff x realization %)
A4: Contribution per use | B4: Realized revenue per use - Variable cost per use
A5: Break-even usage per day | B5: Fixed monthly cost / Contribution per use / Working days per month
A6: Maintenance schedule | B6: Warranty (0 cost) -> CMC (flat annual cost) -> AMC (flat annual cost), by year
A7: EMI (loan) | B7: Standard amortizing-loan formula; Excel's native PMT function
A8: NPV | B8: Sum of discounted cash flows minus the initial investment; Excel's native NPV function
A9: IRR | B9: The discount rate at which NPV = 0; Excel's native IRR function
A10: Cash received by month | B10: Each payer's share of a month's realized revenue collected ceil(days-to-collect / 30) months later
A11: Monthly tab vs. dashboard headline figures | B11: The Monthly tab's Billed/Realized revenue ramp up month by month per the Ramp % column above. The CapexIQ dashboard's own monthly revenue and ROI figures are shown at mature (fully ramped-up) utilization, so they will match this tab's later, fully-ramped months rather than month 1 whenever a utilization ramp is set. NPV/IRR here and on the dashboard both already account for the ramp-up period.
